Traceback (most recent call last):
  File "/opt/hostedtoolcache/Python/3.8.17/x64/lib/python3.8/site-packages/jupyter_cache/executors/utils.py", line 58, in single_nb_execution
    executenb(
  File "/opt/hostedtoolcache/Python/3.8.17/x64/lib/python3.8/site-packages/nbclient/client.py", line 1305, in execute
    return NotebookClient(nb=nb, resources=resources, km=km, **kwargs).execute()
  File "/opt/hostedtoolcache/Python/3.8.17/x64/lib/python3.8/site-packages/jupyter_core/utils/__init__.py", line 166, in wrapped
    return loop.run_until_complete(inner)
  File "/opt/hostedtoolcache/Python/3.8.17/x64/lib/python3.8/asyncio/base_events.py", line 616, in run_until_complete
    return future.result()
  File "/opt/hostedtoolcache/Python/3.8.17/x64/lib/python3.8/site-packages/nbclient/client.py", line 705, in async_execute
    await self.async_execute_cell(
  File "/opt/hostedtoolcache/Python/3.8.17/x64/lib/python3.8/site-packages/nbclient/client.py", line 1058, in async_execute_cell
    await self._check_raise_for_error(cell, cell_index, exec_reply)
  File "/opt/hostedtoolcache/Python/3.8.17/x64/lib/python3.8/site-packages/nbclient/client.py", line 914, in _check_raise_for_error
    raise CellExecutionError.from_cell_and_msg(cell, exec_reply_content)
nbclient.exceptions.CellExecutionError: An error occurred while executing the following cell:
------------------
if(dataset_idx < 100 and dataset_idx > 1):
    df = get_metadata('datasets_10.json', dataset_idx)
    input_list = []
    #data_string = df.to_string(index=False, header=False)
    for entity in df:
        print(entity, ':', df[entity][0])
        input_list.append(df[entity][0])
else:
    print('input number in the interval from 0 to 99')
------------------


[0;31m---------------------------------------------------------------------------[0m
[0;31mFileNotFoundError[0m                         Traceback (most recent call last)
Cell [0;32mIn[3], line 2[0m
[1;32m      1[0m [38;5;28;01mif[39;00m(dataset_idx [38;5;241m<[39m [38;5;241m100[39m [38;5;129;01mand[39;00m dataset_idx [38;5;241m>[39m [38;5;241m1[39m):
[0;32m----> 2[0m     df [38;5;241m=[39m [43mget_metadata[49m[43m([49m[38;5;124;43m'[39;49m[38;5;124;43mdatasets_10.json[39;49m[38;5;124;43m'[39;49m[43m,[49m[43m [49m[43mdataset_idx[49m[43m)[49m
[1;32m      3[0m     input_list [38;5;241m=[39m []
[1;32m      4[0m     [38;5;66;03m#data_string = df.to_string(index=False, header=False)[39;00m

Cell [0;32mIn[1], line 5[0m, in [0;36mget_metadata[0;34m(data, data_index)[0m
[1;32m      4[0m [38;5;28;01mdef[39;00m [38;5;21mget_metadata[39m(data, data_index):
[0;32m----> 5[0m     [38;5;28;01mwith[39;00m [38;5;28;43mopen[39;49m[43m([49m[43mdata[49m[43m,[49m[43m [49m[38;5;124;43m'[39;49m[38;5;124;43mr[39;49m[38;5;124;43m'[39;49m[43m,[49m[43m [49m[43mencoding[49m[38;5;241;43m=[39;49m[38;5;124;43m'[39;49m[38;5;124;43mutf-8[39;49m[38;5;124;43m'[39;49m[43m)[49m [38;5;28;01mas[39;00m file:
[1;32m      6[0m         data [38;5;241m=[39m json[38;5;241m.[39mload(file)
[1;32m      8[0m         title [38;5;241m=[39m data[data_index][[38;5;124m'[39m[38;5;124mtitle[39m[38;5;124m'[39m]

File [0;32m/opt/hostedtoolcache/Python/3.8.17/x64/lib/python3.8/site-packages/IPython/core/interactiveshell.py:284[0m, in [0;36m_modified_open[0;34m(file, *args, **kwargs)[0m
[1;32m    277[0m [38;5;28;01mif[39;00m file [38;5;129;01min[39;00m {[38;5;241m0[39m, [38;5;241m1[39m, [38;5;241m2[39m}:
[1;32m    278[0m     [38;5;28;01mraise[39;00m [38;5;167;01mValueError[39;00m(
[1;32m    279[0m         [38;5;124mf[39m[38;5;124m"[39m[38;5;124mIPython won[39m[38;5;124m'[39m[38;5;124mt let you open fd=[39m[38;5;132;01m{[39;00mfile[38;5;132;01m}[39;00m[38;5;124m by default [39m[38;5;124m"[39m
[1;32m    280[0m         [38;5;124m"[39m[38;5;124mas it is likely to crash IPython. If you know what you are doing, [39m[38;5;124m"[39m
[1;32m    281[0m         [38;5;124m"[39m[38;5;124myou can use builtins[39m[38;5;124m'[39m[38;5;124m open.[39m[38;5;124m"[39m
[1;32m    282[0m     )
[0;32m--> 284[0m [38;5;28;01mreturn[39;00m [43mio_open[49m[43m([49m[43mfile[49m[43m,[49m[43m [49m[38;5;241;43m*[39;49m[43margs[49m[43m,[49m[43m [49m[38;5;241;43m*[39;49m[38;5;241;43m*[39;49m[43mkwargs[49m[43m)[49m

[0;31mFileNotFoundError[0m: [Errno 2] No such file or directory: 'datasets_10.json'

