Traceback (most recent call last):
  File "/opt/hostedtoolcache/Python/3.8.17/x64/lib/python3.8/site-packages/jupyter_cache/executors/utils.py", line 58, in single_nb_execution
    executenb(
  File "/opt/hostedtoolcache/Python/3.8.17/x64/lib/python3.8/site-packages/nbclient/client.py", line 1305, in execute
    return NotebookClient(nb=nb, resources=resources, km=km, **kwargs).execute()
  File "/opt/hostedtoolcache/Python/3.8.17/x64/lib/python3.8/site-packages/jupyter_core/utils/__init__.py", line 166, in wrapped
    return loop.run_until_complete(inner)
  File "/opt/hostedtoolcache/Python/3.8.17/x64/lib/python3.8/asyncio/base_events.py", line 616, in run_until_complete
    return future.result()
  File "/opt/hostedtoolcache/Python/3.8.17/x64/lib/python3.8/site-packages/nbclient/client.py", line 705, in async_execute
    await self.async_execute_cell(
  File "/opt/hostedtoolcache/Python/3.8.17/x64/lib/python3.8/site-packages/nbclient/client.py", line 1058, in async_execute_cell
    await self._check_raise_for_error(cell, cell_index, exec_reply)
  File "/opt/hostedtoolcache/Python/3.8.17/x64/lib/python3.8/site-packages/nbclient/client.py", line 914, in _check_raise_for_error
    raise CellExecutionError.from_cell_and_msg(cell, exec_reply_content)
nbclient.exceptions.CellExecutionError: An error occurred while executing the following cell:
------------------
if(dataset_idx < 100 and dataset_idx > 1):
    df = get_metadata('../../assets/example_depositar_data.json', dataset_idx)
    input_list = []
    for entity in df:
        print(entity, ':', df[entity][0])
        input_list.append(df[entity][0])
else:
    print('input number in the interval from 0 to 99')
------------------


[0;31m---------------------------------------------------------------------------[0m
[0;31mNameError[0m                                 Traceback (most recent call last)
Cell [0;32mIn[3], line 2[0m
[1;32m      1[0m [38;5;28;01mif[39;00m(dataset_idx [38;5;241m<[39m [38;5;241m100[39m [38;5;129;01mand[39;00m dataset_idx [38;5;241m>[39m [38;5;241m1[39m):
[0;32m----> 2[0m     df [38;5;241m=[39m [43mget_metadata[49m[43m([49m[38;5;124;43m'[39;49m[38;5;124;43m../../assets/example_depositar_data.json[39;49m[38;5;124;43m'[39;49m[43m,[49m[43m [49m[43mdataset_idx[49m[43m)[49m
[1;32m      3[0m     input_list [38;5;241m=[39m []
[1;32m      4[0m     [38;5;28;01mfor[39;00m entity [38;5;129;01min[39;00m df:

Cell [0;32mIn[1], line 6[0m, in [0;36mget_metadata[0;34m(data_path, data_index)[0m
[1;32m      5[0m [38;5;28;01mdef[39;00m [38;5;21mget_metadata[39m(data_path, data_index):
[0;32m----> 6[0m     [38;5;28;01mwith[39;00m [43mwarnings[49m[38;5;241m.[39mcatch_warnings():
[1;32m      7[0m         warnings[38;5;241m.[39msimplefilter(action[38;5;241m=[39m[38;5;124m'[39m[38;5;124mignore[39m[38;5;124m'[39m, category[38;5;241m=[39m[38;5;167;01mFutureWarning[39;00m)
[1;32m      8[0m         data [38;5;241m=[39m pd[38;5;241m.[39mread_json(data_path)

[0;31mNameError[0m: name 'warnings' is not defined

